<?xml version="1.0"?>
<robot xmlns:xacro="http://www.ros.org/wiki/xacro">
  
  <xacro:include filename="inertial_macros.xacro"/>

  <material name="white">
    <color rgba="1 1 1 1"/>
  </material>

  <material name="orange">
      <color rgba="1 0.3 0.1 1"/>
  </material>

  <material name="blue">
      <color rgba="0.2 0.2 1 1"/>
  </material>

  <material name="black">
      <color rgba="0 0 0 1"/>
  </material>
  
  <!-- base link -->

  <link name="base_link">

  </link>
  
  <!-- base footprint link -->

  <joint name="base_footprint_joint" type="fixed">
        <parent link="chassis"/>
        <child link="base_footprint"/>
        <origin xyz="0 0 0" rpy="0 0 0"/>
  </joint>

  <link name="base_footprint">
  </link>

  <!-- chassis link -->

  <joint name="chassis_joint" type="fixed">
    <parent link="base_link"/>
    <child link="chassis"/>
    <origin xyz="-0.25 0 0.07"/>
  </joint>

  <link name="chassis">
    <visual>
      <origin xyz="0.25 0 0.0585"/>
      <geometry>
        <box size="0.5 0.5 0.117"/>
      </geometry>
      <material name="white"/>
    </visual>
    <collision>
      <origin xyz="0.25 0 0.0585"/>
      <geometry>
        <box size="0.5 0.5 0.117"/>
      </geometry>
    </collision>
    <xacro:inertial_box mass="5" x="0.5" y="0.5" z="1">
        <origin xyz="0.25 0 0.0585" rpy="0 0 0"/>
    </xacro:inertial_box>
  </link>  

    <!-- left wheel link -->

    <joint name="left_wheel_joint" type="continuous">
    <parent link="base_link"/>
    <child link="left_wheel"/>
    <origin xyz="0 0.12 0.035" rpy="-${pi/2} 0 0"/>
    <axis xyz="0 0 1"/>
  </joint>

  <link name="left_wheel">
    <visual>     
      <geometry>
        <cylinder radius="0.035" length="0.015"/>
      </geometry>
      <material name="orange"/>
    </visual>
    <collision>     
      <geometry>
        <cylinder radius="0.035" length="0.015"/>
      </geometry>
    </collision>
    <xacro:inertial_cylinder mass="0.2" length="0.015" radius="0.035">
        <origin xyz="0 0 0" rpy="0 0 0"/>
    </xacro:inertial_cylinder>
  </link> 
  
  <!-- right wheel link -->

    <joint name="right_wheel_joint" type="continuous">
    <parent link="base_link"/>
    <child link="right_wheel"/>
    <origin xyz="0 -0.12 0.035" rpy="${pi/2} 0 0"/>
    <axis xyz="0 0 -1"/>
  </joint>

  <link name="right_wheel">
    <visual>    
      <geometry>
        <cylinder radius="0.035" length="0.015"/>
      </geometry>
      <material name="orange"/>
    </visual>
    <collision>    
      <geometry>
        <cylinder radius="0.035" length="0.015"/>
      </geometry>
    </collision>
    <xacro:inertial_cylinder mass="0.2" length="0.015" radius="0.035">
        <origin xyz="0 0 0" rpy="0 0 0"/>
    </xacro:inertial_cylinder>
  </link> 

  <!-- caster wheel UL link  -->

    <joint name="caster_wheel_UL_joint" type="fixed">
    <parent link="base_link"/>
    <child link="caster_wheel_UL"/>
    <origin xyz="${0.25-0.047} ${0.25-(0.059/2)} 0.035" rpy="-${pi/2} 0 0"/>
    <axis xyz="0 0 1"/>
  </joint>

  <link name="caster_wheel_UL">
    <visual>     
      <geometry>
        <cylinder radius="0.035" length="0.019"/>
      </geometry>
      <material name="blue"/>
    </visual>
    <collision>     
      <geometry>
        <cylinder radius="0.035" length="0.019"/>
      </geometry>
    </collision>
    <xacro:inertial_cylinder mass="0.35" length="0.019" radius="0.035">
        <origin xyz="0 0 0" rpy="0 0 0"/>
    </xacro:inertial_cylinder>
  </link>

  <!-- caster wheel UR link  -->

    <joint name="caster_wheel_UR_joint" type="fixed">
    <parent link="base_link"/>
    <child link="caster_wheel_UR"/>
    <origin xyz="${0.25-0.047} ${-0.25+(0.059/2)} 0.035" rpy="${pi/2} 0 0"/>
    <axis xyz="0 0 1"/>
  </joint>

  <link name="caster_wheel_UR">
    <visual>      
      <geometry>
        <cylinder radius="0.035" length="0.019"/>
      </geometry>
      <material name="blue"/>
    </visual>
    <collision>      
      <geometry>
        <cylinder radius="0.035" length="0.019"/>
      </geometry>
    </collision>
    <xacro:inertial_cylinder mass="0.35" length="0.019" radius="0.035">
        <origin xyz="0 0 0" rpy="0 0 0"/>
    </xacro:inertial_cylinder>
  </link>

  <!-- caster wheel LL link  -->

    <joint name="caster_wheel_LL_joint" type="fixed">
    <parent link="base_link"/>
    <child link="caster_wheel_LL"/>
    <origin xyz="${-0.25+0.047} ${0.25-(0.059/2)} 0.035" rpy="-${pi/2} 0 0"/>
    <axis xyz="0 0 1"/>
  </joint>

  <link name="caster_wheel_LL">
    <visual>     
      <geometry>
        <cylinder radius="0.035" length="0.019"/>
      </geometry>
      <material name="blue"/>
    </visual>
    <collision>      
      <geometry>
        <cylinder radius="0.035" length="0.019"/>
      </geometry>
    </collision>
    <xacro:inertial_cylinder mass="0.35" length="0.019" radius="0.035">
        <origin xyz="0 0 0" rpy="0 0 0"/>
    </xacro:inertial_cylinder>
  </link>

<!-- caster wheel LR link  -->

    <joint name="caster_wheel_LR_joint" type="fixed">
    <parent link="base_link"/>
    <child link="caster_wheel_LR"/>
    <origin xyz="${-0.25+0.047} ${-0.25+(0.059/2)} 0.035" rpy="${pi/2} 0 0"/>
    <axis xyz="0 0 1"/>
  </joint>

  <link name="caster_wheel_LR">
    <visual>      
      <geometry>
        <cylinder radius="0.035" length="0.019"/>
      </geometry>
      <material name="blue"/>
    </visual>
    <collision>      
      <geometry>
        <cylinder radius="0.035" length="0.019"/>
      </geometry>
    </collision>
    <xacro:inertial_cylinder mass="0.35" length="0.019" radius="0.035">
        <origin xyz="0 0 0" rpy="0 0 0"/>
    </xacro:inertial_cylinder>
  </link>
</robot>